Workbook

Sheet Vulnerability Detection - GPT4o
B1: Baseline (description + file) | C1: Baseline (description + method) | D1: Baseline (description + hunk) | E1: Baseline (description) | F1: Fine-tuned (description + file) | G1: Fine-tuned (description + method) | H1: Fine-tuned (description + hunk) | I1: Fine-tuned (description)
A2: Is_vulnerable = Null | B2: 0 | C2: 0 | D2: 1 | E2: 0 | F2: 0 | G2: 0 | H2: 0 | I2: 0
A3: Correct Is_vulnerable | B3: 328 | C3: 328 | D3: 327 | E3: 328 | F3: 328 | G3: 328 | H3: 328 | I3: 328
A4: Incorrect Is_vulnerable | B4: 0 | C4: 0 | D4: 0 | E4: 0 | F4: 0 | G4: 0 | H4: 0 | I4: 0
A5: Is_sec_vulnerable = Null | B5: 0 | C5: 0 | D5: 1 | E5: 0 | F5: 0 | G5: 0 | H5: 0 | I5: 0
A6: Correct Is_sec_vulnerable | B6: 328 | C6: 326 | D6: 325 | E6: 323 | F6: 328 | G6: 328 | H6: 328 | I6: 328
A7: Incorrect Is_sec_vulnerable | B7: 0 | C7: 2 | D7: 2 | E7: 5 | F7: 0 | G7: 0 | H7: 0 | I7: 0
A8: CWE = Null | B8: 0 | C8: 0 | D8: 1 | E8: 0 | F8: 2 | G8: 1 | H8: 0 | I8: 0
A9: CWE = [] | B9: 0 | C9: 0 | D9: 2 | E9: 2 | F9: 0 | G9: 0 | H9: 0 | I9: 0
A10: Correct CWE | B10: 98 | C10: 84 | D10: 94 | E10: 81 | F10: 127 | G10: 125 | H10: 124 | I10: 129
A11: gt CWE ⊆ pr CWE | B11: 161 | C11: 153 | D11: 159 | E11: 152 | F11: 150 | G11: 142 | H11: 144 | I11: 148
A12: pr CWE ⊆ gt CWE | B12: 111 | C12: 96 | D12: 108 | E12: 92 | F12: 149 | G12: 147 | H12: 142 | I12: 152
A13: Overlapped CWE | B13: 12 | C13: 18 | D13: 10 | E13: 18 | F13: 8 | G13: 2 | H13: 5 | I13: 6
... A34: Overall (gt CWE ⊆ pr CWE, 1.5) | B34: 38 | C34: 34 | D34: 34 | E34: 35 | F34: 16 | G34: 33 | H34: 17 | I34: 33
A38: Total Number of Records | B38: 328

Sheet Vul. Det. Noise - GPT
B1: baseline - 0 noise | C1: baseline - 1 noise | D1: baseline - 2 noises | E1: baseline - 3 noises | F1: baseline - 4 noises | G1: baseline - 5 noises | H1: CASEY - 0 noise | I1: CASEY - 1 noises | J1: CASEY - 2 noises | K1: CASEY - 3 noises | L1: CASEY - 4 noises | M1: CASEY - 5 noises
A2: Is_vulnerable = Null | B2: 0 | C2: 0 | D2: 0 | E2: 0 | F2: 0 | G2: 0 | H2: 1 | I2: 0 | J2: 0 | K2: 0 | L2: 0 | M2: 1
A3: Correct Is_vulnerable | B3: 100 | C3: 100 | D3: 100 | E3: 100 | F3: 100 | G3: 100 | H3: 99 | I3: 100 | J3: 100 | K3: 100 | L3: 100 | M3: 99
A4: Incorrect Is_vulnerable | B4: 0 | C4: 0 | D4: 0 | E4: 0 | F4: 0 | G4: 0 | H4: 0 | I4: 0 | J4: 0 | K4: 0 | L4: 0 | M4: 0
A5: Is_sec_vulnerable = Null | B5: 0 | C5: 0 | D5: 0 | E5: 0 | F5: 0 | G5: 0 | H5: 1 | I5: 0 | J5: 0 | K5: 0 | L5: 0 | M5: 1
A6: Correct Is_sec_vulnerable | B6: 99 | C6: 99 | D6: 99 | E6: 99 | F6: 99 | G6: 99 | H6: 99 | I6: 100 | J6: 100 | K6: 100 | L6: 100 | M6: 99
A7: Incorrect Is_sec_vulnerable | B7: 1 | C7: 1 | D7: 1 | E7: 1 | F7: 1 | G7: 1 | H7: 0 | I7: 0 | J7: 0 | K7: 0 | L7: 0 | M7: 0
A8: CWE = Null | B8: 0 | C8: 0 | D8: 0 | E8: 0 | F8: 0 | G8: 0 | H8: 1 | I8: 0 | J8: 0 | K8: 0 | L8: 0 | M8: 1
A9: CWE = [] | B9: 1 | C9: 1 | D9: 0 | E9: 1 | F9: 1 | G9: 0 | H9: 0 | I9: 0 | J9: 0 | K9: 0 | L9: 0 | M9: 0
A10: Correct CWE | B10: 29 | C10: 23 | D10: 27 | E10: 27 | F10: 28 | G10: 25 | H10: 40 | I10: 42 | J10: 42 | K10: 44 | L10: 42 | M10: 41
A11: gt CWE ⊆ pr CWE | B11: 48 | C11: 41 | D11: 47 | E11: 46 | F11: 44 | G11: 45 | H11: 43 | I11: 43 | J11: 47 | K11: 47 | L11: 45 | M11: 45
A12: pr CWE ⊆ gt CWE | B12: 34 | C12: 27 | D12: 29 | E12: 29 | F12: 30 | G12: 28 | H12: 45 | I12: 47 | J12: 47 | K12: 49 | L12: 46 | M12: 47
A13: Overlapped CWE | B13: 3 | C13: 8 | D13: 7 | E13: 6 | F13: 8 | G13: 7 | H13: 3 | I13: 3 | J13: 4 | K13: 2 | L13: 2 | M13: 3
... A51: Severity Label F1-score - CRITICAL | B51: 0.353 | C51: 0.267 | D51: 0.3 | E51: 0.353 | F51: 0.353 | G51: 0.25 | H51: 0.333 | I51: 0.5 | J51: 0.364 | K51: 0.429 | L51: 0.571 | M51: 0.308
A53: Type | B53: desription + method
A54: Total Number of Records | B54: 100
B57: Applying noises
A58: baseline - gpt
B59: 0 | C59: 1 | D59: 2 | E59: 3 | F59: 4 | G59: 5
A60: is vulnerable | B60: 100 | C60: 100 | D60: 100 | E60: 100 | F60: 100 | G60: 100
A61: is security vulnerable | B61: 99 | C61: 99 | D61: 99 | E61: 99 | F61: 99 | G61: 99
A62: cwe identification | B62: 27 | C62: 19 | D62: 21 | E62: 21 | F62: 22 | G62: 19
A63: severity identification | B63: 34 | C63: 30 | D63: 30 | E63: 31 | F63: 28 | G63: 29
A64: CVSS score (threshold=0) | B64: 4 | C64: 4 | D64: 3 | E64: 4 | F64: 4 | G64: 4
A66: gpt
B67: 0 | C67: 1 | D67: 2 | E67: 3 | F67: 4 | G67: 5
A68: is vulnerable | B68: 99 | C68: 99 | D68: 99 | E68: 99 | F68: 99 | G68: 98
A69: is security vulnerable | B69: 100 | C69: 100 | D69: 100 | E69: 100 | F69: 100 | G69: 99
A70: cwe identification | B70: 41 | C70: 39 | D70: 39 | E70: 39 | F70: 39 | G70: 37
A71: severity identification | B71: 53 | C71: 48 | D71: 47 | E71: 46 | F71: 46 | G71: 46
A72: CVSS score (threshold=0) | B72: 8 | C72: 7 | D72: 6 | E72: 6 | F72: 6 | G72: 6
A74: gpt - deviation from 0 noises
B75: 0 | C75: 1 | D75: 2 | E75: 3 | F75: 4 | G75: 5
A76: is vulnerable | B76: 0 | C76: =B68-C68 -> 0 | D76: =B68-D68 -> 0 | E76: =B68-E68 -> 0 | F76: =B68-F68 -> 0 | G76: =B68-G68 -> 1
A77: is security vulnerable | B77: 0 | C77: =B69-C69 -> 0 | D77: =B69-D69 -> 0 | E77: =B69-E69 -> 0 | F77: =B69-F69 -> 0 | G77: =B69-G69 -> 1
A78: cwe identification | B78: 0 | C78: =B70-C70 -> 2 | D78: =B70-D70 -> 2 | E78: =B70-E70 -> 2 | F78: =B70-F70 -> 2 | G78: =B70-G70 -> 4
A79: severity identification | B79: 0 | C79: =B71-C71 -> 5 | D79: =B71-D71 -> 6 | E79: =B71-E71 -> 7 | F79: =B71-F71 -> 7 | G79: =B71-G71 -> 7
A80: CVSS score (threshold=0) | B80: 0 | C80: =B72-C72 -> 1 | D80: =B72-D72 -> 2 | E80: =B72-E72 -> 2 | F80: =B72-F72 -> 2 | G80: =B72-G72 -> 2
C142: B

Sheet Vulnerability Detection - LLAMA
B1: Baseline (description + file) | C1: Baseline (description + method) | D1: Baseline (description + hunk) | E1: Baseline (description) | F1: Fine-tuned (description + file) | G1: Fine-tuned (description + method) | H1: Fine-tuned (description + hunk) | I1: Fine-tuned (description)
A2: Is_vulnerable = Null | B2: 1 | C2: 0 | D2: 0 | E2: 8 | F2: 0 | G2: 0 | H2: 0 | I2: 0
A3: Correct Is_vulnerable | B3: 327 | C3: 328 | D3: 328 | E3: 309 | F3: 328 | G3: 328 | H3: 328 | I3: 328
A4: Incorrect Is_vulnerable | B4: 0 | C4: 0 | D4: 0 | E4: 11 | F4: 0 | G4: 0 | H4: 0 | I4: 0
A5: Is_sec_vulnerable = Null | B5: 1 | C5: 0 | D5: 0 | E5: 8 | F5: 0 | G5: 0 | H5: 0 | I5: 0
A6: Correct Is_sec_vulnerable | B6: 327 | C6: 328 | D6: 328 | E6: 310 | F6: 328 | G6: 328 | H6: 328 | I6: 328
A7: Incorrect Is_sec_vulnerable | B7: 0 | C7: 0 | D7: 0 | E7: 10 | F7: 0 | G7: 0 | H7: 0 | I7: 0
A8: CWE = Null | B8: 1 | C8: 0 | D8: 0 | E8: 8 | F8: 0 | G8: 0 | H8: 0 | I8: 0
A9: CWE = [] | B9: 0 | C9: 0 | D9: 0 | E9: 11 | F9: 0 | G9: 0 | H9: 0 | I9: 0
A10: Correct CWE | B10: 0 | C10: 0 | D10: 0 | E10: 0 | F10: 95 | G10: 105 | H10: 104 | I10: 113
A11: gt CWE ⊆ pr CWE | B11: 46 | C11: 52 | D11: 49 | E11: 58 | F11: 95 | G11: 105 | H11: 104 | I11: 113
A12: pr CWE ⊆ gt CWE | B12: 2 | C12: 2 | D12: 2 | E12: 2 | F12: 108 | G12: 118 | H12: 119 | I12: 126
A13: Overlapped CWE | B13: 11 | C13: 8 | D13: 8 | E13: 10 | F13: 0 | G13: 0 | H13: 0 | I13: 0
... A34: Overall (gt CWE ⊆ pr CWE, 1.5) | B34: 0 | C34: 16 | D34: 8 | E34: 12 | F34: 22 | G34: 14 | H34: 23 | I34: 31
A38: Total Number of Records | B38: 328

Sheet Vul. Det. Noise - LLAMA
B1: 0 noise | C1: 1 noise | D1: 2 noises | E1: 3 noises | F1: 4 noises | G1: 5 noises | H1: CASEY - 0 noise | I1: CASEY - 1 noises | J1: CASEY - 2 noises | K1: CASEY - 3 noises | L1: CASEY - 4 noises | M1: CASEY - 5 noises
A2: Is_vulnerable = Null | B2: 0 | C2: 0 | D2: 0 | E2: 0 | F2: 0 | G2: 0 | H2: 0 | I2: 0 | J2: 0 | K2: 0 | L2: 0 | M2: 0
A3: Correct Is_vulnerable | B3: 99 | C3: 100 | D3: 100 | E3: 99 | F3: 100 | G3: 100 | H3: 100 | I3: 100 | J3: 100 | K3: 100 | L3: 100 | M3: 100
A4: Incorrect Is_vulnerable | B4: 1 | C4: 0 | D4: 0 | E4: 1 | F4: 0 | G4: 0 | H4: 0 | I4: 0 | J4: 0 | K4: 0 | L4: 0 | M4: 0
A5: Is_sec_vulnerable = Null | B5: 0 | C5: 0 | D5: 0 | E5: 0 | F5: 0 | G5: 0 | H5: 0 | I5: 0 | J5: 0 | K5: 0 | L5: 0 | M5: 0
A6: Correct Is_sec_vulnerable | B6: 99 | C6: 100 | D6: 100 | E6: 99 | F6: 99 | G6: 99 | H6: 100 | I6: 100 | J6: 100 | K6: 100 | L6: 100 | M6: 100
A7: Incorrect Is_sec_vulnerable | B7: 1 | C7: 0 | D7: 0 | E7: 1 | F7: 1 | G7: 1 | H7: 0 | I7: 0 | J7: 0 | K7: 0 | L7: 0 | M7: 0
A8: CWE = Null | B8: 0 | C8: 0 | D8: 0 | E8: 0 | F8: 0 | G8: 0 | H8: 0 | I8: 0 | J8: 0 | K8: 0 | L8: 0 | M8: 0
A9: CWE = [] | B9: 1 | C9: 0 | D9: 0 | E9: 1 | F9: 1 | G9: 1 | H9: 0 | I9: 0 | J9: 0 | K9: 0 | L9: 0 | M9: 0
A10: Correct CWE | B10: 0 | C10: 0 | D10: 0 | E10: 0 | F10: 0 | G10: 0 | H10: 32 | I10: 32 | J10: 32 | K10: 32 | L10: 32 | M10: 31
A11: gt CWE ⊆ pr CWE | B11: 17 | C11: 12 | D11: 13 | E11: 12 | F11: 13 | G11: 10 | H11: 32 | I11: 32 | J11: 32 | K11: 32 | L11: 32 | M11: 31
A12: pr CWE ⊆ gt CWE | B12: 1 | C12: 1 | D12: 3 | E12: 1 | F12: 1 | G12: 1 | H12: 36 | I12: 36 | J12: 36 | K12: 36 | L12: 36 | M12: 35
A13: Overlapped CWE | B13: 3 | C13: 4 | D13: 1 | E13: 4 | F13: 3 | G13: 2 | H13: 0 | I13: 0 | J13: 0 | K13: 0 | L13: 0 | M13: 0
... A51: Severity Label F1-score - CRITICAL | B51: 0.279 | C51: 0.24 | D51: 0.28 | E51: 0.25 | F51: 0.304 | G51: 0.308 | H51: 0.067 | I51: 0.114 | J51: 0.062 | K51: 0.114 | L51: 0.167 | M51: 0.158
A53: Type | B53: desription + method
A54: Total Number of Records | B54: 100
B57: Applying noises
A58: baseline - llama
B59: 0 | C59: 1 | D59: 2 | E59: 3 | F59: 4 | G59: 5
A60: is vulnerable | B60: 99 | C60: 99 | D60: 99 | E60: 99 | F60: 99 | G60: 99
A61: is security vulnerable | B61: 99 | C61: 99 | D61: 99 | E61: 99 | F61: 99 | G61: 99
A62: cwe identification | B62: 0 | C62: 0 | D62: 0 | E62: 0 | F62: 0 | G62: 0
A63: severity identification | B63: 45 | C63: 38 | D63: 38 | E63: 38 | F63: 36 | G63: 36
A64: CVSS score (threshold=0) | B64: 3 | C64: 2 | D64: 2 | E64: 3 | F64: 3 | G64: 3
A66: llama
B67: 0 | C67: 1 | D67: 2 | E67: 3 | F67: 4 | G67: 5
A68: is vulnerable | B68: 100 | C68: 100 | D68: 100 | E68: 100 | F68: 100 | G68: 100
A69: is security vulnerable | B69: 100 | C69: 100 | D69: 100 | E69: 100 | F69: 100 | G69: 100
A70: cwe identification | B70: 32 | C70: 31 | D70: 31 | E70: 31 | F70: 31 | G70: 31
A71: severity identification | B71: 27 | C71: 25 | D71: 21 | E71: 21 | F71: 21 | G71: 17
A72: CVSS score (threshold=0) | B72: 4 | C72: 3 | D72: 3 | E72: 3 | F72: 3 | G72: 3
A74: llama- deviation from 0 noises
B75: 0 | C75: 1 | D75: 2 | E75: 3 | F75: 4 | G75: 5
A76: is vulnerable | B76: 0 | C76: =B68-C68 -> 0 | D76: =B68-D68 -> 0 | E76: =B68-E68 -> 0 | F76: =B68-F68 -> 0 | G76: =B68-G68 -> 0
A77: is security vulnerable | B77: 0 | C77: =B69-C69 -> 0 | D77: =B69-D69 -> 0 | E77: =B69-E69 -> 0 | F77: =B69-F69 -> 0 | G77: =B69-G69 -> 0
A78: cwe identification | B78: 0 | C78: =B70-C70 -> 1 | D78: =B70-D70 -> 1 | E78: =B70-E70 -> 1 | F78: =B70-F70 -> 1 | G78: =B70-G70 -> 1
A79: severity identification | B79: 0 | C79: =B71-C71 -> 2 | D79: =B71-D71 -> 6 | E79: =B71-E71 -> 6 | F79: =B71-F71 -> 6 | G79: =B71-G71 -> 10
A80: CVSS score (threshold=0) | B80: 0 | C80: =B72-C72 -> 1 | D80: =B72-D72 -> 1 | E80: =B72-E72 -> 1 | F80: =B72-F72 -> 1 | G80: =B72-G72 -> 1
H86: ›

Sheet GPT4o Plots
C1: Percentage | G1: Baseline (Raw) | AA1: Generated By Python
B2: Metric | C2: Input Type | D2: Baseline | E2: Fine-tuned | G2: Metric | H2: Minimum Threshold | I2: Description + file | J2: Description + method | K2: Description + hunk | L2: Description
B3: Correct Is_vulnerable | C3: Description + File | D3: ='Vulnerability Detection - GPT4o'!B3/'Vulnerability Detection - GPT4o'!B38*100 -> 100 | E3: ='Vulnerability Detection - GPT4o'!F3/'Vulnerability Detection - GPT4o'!B38*100 -> 100 | G3: Score Proximity | H3: 0 | I3: ='Vulnerability Detection - GPT4o'!B19 -> 18 | J3: ='Vulnerability Detection - GPT4o'!C19 -> 18 | K3: ='Vulnerability Detection - GPT4o'!D19 -> 17 | L3: ='Vulnerability Detection - GPT4o'!E19 -> 15
B4: Correct Is_vulnerable | C4: Description + Method | D4: ='Vulnerability Detection - GPT4o'!C3/'Vulnerability Detection - GPT4o'!B38*100 -> 100 | E4: ='Vulnerability Detection - GPT4o'!G3/'Vulnerability Detection - GPT4o'!B38*100 -> 100 | G4: Score Proximity | H4: 0.5 | I4: ='Vulnerability Detection - GPT4o'!B20 -> 34 | J4: ='Vulnerability Detection - GPT4o'!C20 -> 42 | K4: ='Vulnerability Detection - GPT4o'!D20 -> 43 | L4: ='Vulnerability Detection - GPT4o'!E20 -> 43
B5: Correct Is_vulnerable | C5: Description + Hunk | D5: ='Vulnerability Detection - GPT4o'!D3/'Vulnerability Detection - GPT4o'!B38*100 -> 99.695122 | E5: ='Vulnerability Detection - GPT4o'!H3/'Vulnerability Detection - GPT4o'!B38*100 -> 100 | G5: Score Proximity | H5: 1 | I5: ='Vulnerability Detection - GPT4o'!B21 -> 70 | J5: ='Vulnerability Detection - GPT4o'!C21 -> 78 | K5: ='Vulnerability Detection - GPT4o'!D21 -> 78 | L5: ='Vulnerability Detection - GPT4o'!E21 -> 78
B6: Correct Is_vulnerable | C6: Description | D6: ='Vulnerability Detection - GPT4o'!E3/'Vulnerability Detection - GPT4o'!B38*100 -> 100 | E6: ='Vulnerability Detection - GPT4o'!I3/'Vulnerability Detection - GPT4o'!B38*100 -> 100 | G6: Score Proximity | H6: 1.5 | I6: ='Vulnerability Detection - GPT4o'!B22 -> 61 | J6: ='Vulnerability Detection - GPT4o'!C22 -> 51 | K6: ='Vulnerability Detection - GPT4o'!D22 -> 56 | L6: ='Vulnerability Detection - GPT4o'!E22 -> 59
B7: Correct Is_sec_vulnerable | C7: Description + File | D7: ='Vulnerability Detection - GPT4o'!B6/'Vulnerability Detection - GPT4o'!B38*100 -> 100 | E7: ='Vulnerability Detection - GPT4o'!F6/'Vulnerability Detection - GPT4o'!B38*100 -> 100 | G7: Baseline (Raw)
B8: Correct Is_sec_vulnerable | C8: Description + Method | D8: ='Vulnerability Detection - GPT4o'!C6/'Vulnerability Detection - GPT4o'!B38*100 -> 99.390244 | E8: ='Vulnerability Detection - GPT4o'!G6/'Vulnerability Detection - GPT4o'!B38*100 -> 100 | G8: Metric | H8: Minimum Threshold | I8: Description + file | J8: Description + method | K8: Description + hunk | L8: Description
B9: Correct Is_sec_vulnerable | C9: Description + Hunk | D9: ='Vulnerability Detection - GPT4o'!D6/'Vulnerability Detection - GPT4o'!B38*100 -> 99.085366 | E9: ='Vulnerability Detection - GPT4o'!H6/'Vulnerability Detection - GPT4o'!B38*100 -> 100 | G9: Overall (pr CWE = gt) | H9: 0 | I9: ='Vulnerability Detection - GPT4o'!B23 -> 5 | J9: ='Vulnerability Detection - GPT4o'!C23 -> 6 | K9: ='Vulnerability Detection - GPT4o'!D23 -> 6 | L9: ='Vulnerability Detection - GPT4o'!E23 -> 5
B10: Correct Is_sec_vulnerable | C10: Description | D10: ='Vulnerability Detection - GPT4o'!E6/'Vulnerability Detection - GPT4o'!B38*100 -> 98.47561 | E10: ='Vulnerability Detection - GPT4o'!I6/'Vulnerability Detection - GPT4o'!B38*100 -> 100 | G10: Overall (pr CWE = gt) | H10: 0.5 | I10: ='Vulnerability Detection - GPT4o'!B24 -> 12 | J10: ='Vulnerability Detection - GPT4o'!C24 -> 12 | K10: ='Vulnerability Detection - GPT4o'!D24 -> 13 | L10: ='Vulnerability Detection - GPT4o'!E24 -> 9
B11: Empty CWE | C11: Description + File | D11: ='Vulnerability Detection - GPT4o'!B9/'Vulnerability Detection - GPT4o'!B38*100 -> 0 | E11: ='Vulnerability Detection - GPT4o'!F9/'Vulnerability Detection - GPT4o'!B38*100 -> 0 | G11: Overall (pr CWE = gt) | H11: 1 | I11: ='Vulnerability Detection - GPT4o'!B25 -> 21 | J11: ='Vulnerability Detection - GPT4o'!C25 -> 14 | K11: ='Vulnerability Detection - GPT4o'!D25 -> 22 | L11: ='Vulnerability Detection - GPT4o'!E25 -> 19
B12: Empty CWE | C12: Description + Method | D12: ='Vulnerability Detection - GPT4o'!C9/'Vulnerability Detection - GPT4o'!B38*100 -> 0 | E12: ='Vulnerability Detection - GPT4o'!G9/'Vulnerability Detection - GPT4o'!B38*100 -> 0 | G12: Overall (pr CWE = gt) | H12: 1.5 | I12: ='Vulnerability Detection - GPT4o'!B26 -> 28 | J12: ='Vulnerability Detection - GPT4o'!C26 -> 26 | K12: ='Vulnerability Detection - GPT4o'!D26 -> 27 | L12: ='Vulnerability Detection - GPT4o'!E26 -> 24
B13: Empty CWE | C13: Description + Hunk | D13: ='Vulnerability Detection - GPT4o'!D9/'Vulnerability Detection - GPT4o'!B38*100 -> 0.6097561 | E13: ='Vulnerability Detection - GPT4o'!H9/'Vulnerability Detection - GPT4o'!B38*100 -> 0 | G13: Baseline (Raw)
B14: Empty CWE | C14: Description | D14: ='Vulnerability Detection - GPT4o'!E9/'Vulnerability Detection - GPT4o'!B38*100 -> 0.6097561 | E14: ='Vulnerability Detection - GPT4o'!I9/'Vulnerability Detection - GPT4o'!B38*100 -> 0 | G14: Metric | H14: Minimum Threshold | I14: Description + file | J14: Description + method | K14: Description + hunk | L14: Description
B15: Correct CWE | C15: Description + File | D15: ='Vulnerability Detection - GPT4o'!B10/'Vulnerability Detection - GPT4o'!B38*100 -> 29.878049 | E15: ='Vulnerability Detection - GPT4o'!F10/'Vulnerability Detection - GPT4o'!B38*100 -> 38.719512 | G15: Overall (pr CWE ⊆ gt) | H15: 0 | I15: ='Vulnerability Detection - GPT4o'!B27 -> 5 | J15: ='Vulnerability Detection - GPT4o'!C27 -> 7 | K15: ='Vulnerability Detection - GPT4o'!D27 -> 6 | L15: ='Vulnerability Detection - GPT4o'!E27 -> 5
B16: Correct CWE | C16: Description + Method | D16: ='Vulnerability Detection - GPT4o'!C10/'Vulnerability Detection - GPT4o'!B38*100 -> 25.609756 | E16: ='Vulnerability Detection - GPT4o'!G10/'Vulnerability Detection - GPT4o'!B38*100 -> 38.109756 | G16: Overall (pr CWE ⊆ gt) | H16: 0.5 | I16: ='Vulnerability Detection - GPT4o'!B28 -> 13 | J16: ='Vulnerability Detection - GPT4o'!C28 -> 15 | K16: ='Vulnerability Detection - GPT4o'!D28 -> 16 | L16: ='Vulnerability Detection - GPT4o'!E28 -> 10
B17: Correct CWE | C17: Description + Hunk | D17: ='Vulnerability Detection - GPT4o'!D10/'Vulnerability Detection - GPT4o'!B38*100 -> 28.658537 | E17: ='Vulnerability Detection - GPT4o'!H10/'Vulnerability Detection - GPT4o'!B38*100 -> 37.804878 | G17: Overall (pr CWE ⊆ gt) | H17: 1 | I17: ='Vulnerability Detection - GPT4o'!B29 -> 25 | J17: ='Vulnerability Detection - GPT4o'!C29 -> 17 | K17: ='Vulnerability Detection - GPT4o'!D29 -> 25 | L17: ='Vulnerability Detection - GPT4o'!E29 -> 22
B18: Correct CWE | C18: Description | D18: ='Vulnerability Detection - GPT4o'!E10/'Vulnerability Detection - GPT4o'!B38*100 -> 24.695122 | E18: ='Vulnerability Detection - GPT4o'!I10/'Vulnerability Detection - GPT4o'!B38*100 -> 39.329268 | G18: Overall (pr CWE ⊆ gt) | H18: 1.5 | I18: ='Vulnerability Detection - GPT4o'!B30 -> 28 | J18: ='Vulnerability Detection - GPT4o'!C30 -> 26 | K18: ='Vulnerability Detection - GPT4o'!D30 -> 28 | L18: ='Vulnerability Detection - GPT4o'!E30 -> 26
B19: gt CWE ⊆ pr CWE | C19: Description + File | D19: ='Vulnerability Detection - GPT4o'!B11/'Vulnerability Detection - GPT4o'!B38*100 -> 49.085366 | E19: ='Vulnerability Detection - GPT4o'!F11/'Vulnerability Detection - GPT4o'!B38*100 -> 45.731707 | G19: Baseline (Raw)
B20: gt CWE ⊆ pr CWE | C20: Description + Method | D20: ='Vulnerability Detection - GPT4o'!C11/'Vulnerability Detection - GPT4o'!B38*100 -> 46.646341 | E20: ='Vulnerability Detection - GPT4o'!G11/'Vulnerability Detection - GPT4o'!B38*100 -> 43.292683 | G20: Metric | H20: Minimum Threshold | I20: Description + file | J20: Description + method | K20: Description + hunk | L20: Description
B21: gt CWE ⊆ pr CWE | C21: Description + Hunk | D21: ='Vulnerability Detection - GPT4o'!D11/'Vulnerability Detection - GPT4o'!B38*100 -> 48.47561 | E21: ='Vulnerability Detection - GPT4o'!H11/'Vulnerability Detection - GPT4o'!B38*100 -> 43.902439 | G21: Overall (gt CWE ⊆ pr) | H21: 0 | I21: ='Vulnerability Detection - GPT4o'!B31 -> 8 | J21: ='Vulnerability Detection - GPT4o'!C31 -> 10 | K21: ='Vulnerability Detection - GPT4o'!D31 -> 10 | L21: ='Vulnerability Detection - GPT4o'!E31 -> 8
B22: gt CWE ⊆ pr CWE | C22: Description | D22: ='Vulnerability Detection - GPT4o'!E11/'Vulnerability Detection - GPT4o'!B38*100 -> 46.341463 | E22: ='Vulnerability Detection - GPT4o'!I11/'Vulnerability Detection - GPT4o'!B38*100 -> 45.121951 | G22: Overall (gt CWE ⊆ pr) | H22: 0.5 | I22: ='Vulnerability Detection - GPT4o'!B32 -> 23 | J22: ='Vulnerability Detection - GPT4o'!C32 -> 22 | K22: ='Vulnerability Detection - GPT4o'!D32 -> 24 | L22: ='Vulnerability Detection - GPT4o'!E32 -> 25
B23: pr CWE ⊆ gt CWE | C23: Description + File | D23: ='Vulnerability Detection - GPT4o'!B12/'Vulnerability Detection - GPT4o'!B38*100 -> 33.841463 | E23: ='Vulnerability Detection - GPT4o'!F12/'Vulnerability Detection - GPT4o'!B38*100 -> 45.426829 | G23: Overall (gt CWE ⊆ pr) | H23: 1 | I23: ='Vulnerability Detection - GPT4o'!B33 -> 32 | J23: ='Vulnerability Detection - GPT4o'!C33 -> 34 | K23: ='Vulnerability Detection - GPT4o'!D33 -> 38 | L23: ='Vulnerability Detection - GPT4o'!E33 -> 38
B24: pr CWE ⊆ gt CWE | C24: Description + Method | D24: ='Vulnerability Detection - GPT4o'!C12/'Vulnerability Detection - GPT4o'!B38*100 -> 29.268293 | E24: ='Vulnerability Detection - GPT4o'!G12/'Vulnerability Detection - GPT4o'!B38*100 -> 44.817073 | G24: Overall (gt CWE ⊆ pr) | H24: 1.5 | I24: ='Vulnerability Detection - GPT4o'!B34 -> 38 | J24: ='Vulnerability Detection - GPT4o'!C34 -> 34 | K24: ='Vulnerability Detection - GPT4o'!D34 -> 34 | L24: ='Vulnerability Detection - GPT4o'!E34 -> 35
B25: pr CWE ⊆ gt CWE | C25: Description + Hunk | D25: ='Vulnerability Detection - GPT4o'!D12/'Vulnerability Detection - GPT4o'!B38*100 -> 32.926829 | E25: ='Vulnerability Detection - GPT4o'!H12/'Vulnerability Detection - GPT4o'!B38*100 -> 43.292683 | G25: Baseline (Cumulative)
B26: pr CWE ⊆ gt CWE | C26: Description | D26: ='Vulnerability Detection - GPT4o'!E12/'Vulnerability Detection - GPT4o'!B38*100 -> 28.04878 | E26: ='Vulnerability Detection - GPT4o'!I12/'Vulnerability Detection - GPT4o'!B38*100 -> 46.341463 | G26: Metric | H26: Threshold to cover | I26: Description + file | J26: Description + method | K26: Description + hunk | L26: Description
B27: Overlapped CWE | C27: Description + File | D27: ='Vulnerability Detection - GPT4o'!B13/'Vulnerability Detection - GPT4o'!B38*100 -> 3.6585366 | E27: ='Vulnerability Detection - GPT4o'!F13/'Vulnerability Detection - GPT4o'!B38*100 -> 2.4390244 | G27: Score Proximity | H27: 0 | I27: =I3 -> 18 | J27: =J3 -> 18 | K27: =K3 -> 17 | L27: =L3 -> 15
B28: Overlapped CWE | C28: Description + Method | D28: ='Vulnerability Detection - GPT4o'!C13/'Vulnerability Detection - GPT4o'!B38*100 -> 5.4878049 | E28: ='Vulnerability Detection - GPT4o'!G13/'Vulnerability Detection - GPT4o'!B38*100 -> 0.6097561 | G28: Score Proximity | H28: 0.5 | I28: =I27+I4 -> 52 | J28: =J27+J4 -> 60 | K28: =K27+K4 -> 60 | L28: =L27+L4 -> 58
B29: Overlapped CWE | C29: Description + Hunk | D29: ='Vulnerability Detection - GPT4o'!D13/'Vulnerability Detection - GPT4o'!B38*100 -> 3.0487805 | E29: ='Vulnerability Detection - GPT4o'!H13/'Vulnerability Detection - GPT4o'!B38*100 -> 1.5243902 | G29: Score Proximity | H29: 1 | I29: =I28+I5 -> 122 | J29: =J28+J5 -> 138 | K29: =K28+K5 -> 138 | L29: =L28+L5 -> 136
B30: Overlapped CWE | C30: Description | D30: ='Vulnerability Detection - GPT4o'!E13/'Vulnerability Detection - GPT4o'!B38*100 -> 5.4878049 | E30: ='Vulnerability Detection - GPT4o'!I13/'Vulnerability Detection - GPT4o'!B38*100 -> 1.8292683 | G30: Score Proximity | H30: 1.5 | I30: =I29+I6 -> 183 | J30: =J29+J6 -> 189 | K30: =K29+K6 -> 194 | L30: =L29+L6 -> 195
B31: Non-overlapped CWE | C31: Description + File | D31: ='Vulnerability Detection - GPT4o'!B14/'Vulnerability Detection - GPT4o'!B38*100 -> 43.292683 | E31: ='Vulnerability Detection - GPT4o'!F14/'Vulnerability Detection - GPT4o'!B38*100 -> 44.512195 | G31: Baseline (Cumulative)
B32: Non-overlapped CWE | C32: Description + Method | D32: ='Vulnerability Detection - GPT4o'!C14/'Vulnerability Detection - GPT4o'!B38*100 -> 44.207317 | E32: ='Vulnerability Detection - GPT4o'!G14/'Vulnerability Detection - GPT4o'!B38*100 -> 49.085366 | G32: Metric | H32: Threshold to cover | I32: Description + file | J32: Description + method | K32: Description + hunk | L32: Description
B33: Non-overlapped CWE | C33: Description + Hunk | D33: ='Vulnerability Detection - GPT4o'!D14/'Vulnerability Detection - GPT4o'!B38*100 -> 43.292683 | E33: ='Vulnerability Detection - GPT4o'!H14/'Vulnerability Detection - GPT4o'!B38*100 -> 49.085366 | G33: Overall (pr CWE = gt) | H33: 0 | I33: =I9 -> 5 | J33: =J9 -> 6 | K33: =K9 -> 6 | L33: =L9 -> 5
B34: Non-overlapped CWE | C34: Description | D34: ='Vulnerability Detection - GPT4o'!E14/'Vulnerability Detection - GPT4o'!B38*100 -> 44.207317 | E34: ='Vulnerability Detection - GPT4o'!I14/'Vulnerability Detection - GPT4o'!B38*100 -> 46.036585 | G34: Overall (pr CWE = gt) | H34: 0.5 | I34: =I33+I10 -> 17 | J34: =J33+J10 -> 18 | K34: =K33+K10 -> 19 | L34: =L33+L10 -> 14
B35: Correct severity | C35: Description + File | D35: ='Vulnerability Detection - GPT4o'!B16/'Vulnerability Detection - GPT4o'!B38*100 -> 30.487805 | E35: ='Vulnerability Detection - GPT4o'!F16/'Vulnerability Detection - GPT4o'!B38*100 -> 46.95122 | G35: Overall (pr CWE = gt) | H35: 1 | I35: =I34+I11 -> 38 | J35: =J34+J11 -> 32 | K35: =K34+K11 -> 41 | L35: =L34+L11 -> 33
B36: Correct severity | C36: Description + Method | D36: ='Vulnerability Detection - GPT4o'!C16/'Vulnerability Detection - GPT4o'!B38*100 -> 35.365854 | E36: ='Vulnerability Detection - GPT4o'!G16/'Vulnerability Detection - GPT4o'!B38*100 -> 55.182927 | G36: Overall (pr CWE = gt) | H36: 1.5 | I36: =I35+I12 -> 66 | J36: =J35+J12 -> 58 | K36: =K35+K12 -> 68 | L36: =L35+L12 -> 57
B37: Correct severity | C37: Description + Hunk | D37: ='Vulnerability Detection - GPT4o'!D16/'Vulnerability Detection - GPT4o'!B38*100 -> 38.109756 | E37: ='Vulnerability Detection - GPT4o'!H16/'Vulnerability Detection - GPT4o'!B38*100 -> 52.439024 | G37: Baseline (Cumulative)
B38: Correct severity | C38: Description | D38: ='Vulnerability Detection - GPT4o'!E16/'Vulnerability Detection - GPT4o'!B38*100 -> 37.5 | E38: ='Vulnerability Detection - GPT4o'!I16/'Vulnerability Detection - GPT4o'!B38*100 -> 50.304878 | G38: Metric | H38: Threshold to cover | I38: Description + file | J38: Description + method | K38: Description + hunk | L38: Description
G39: Overall (pr CWE ⊆ gt) | H39: 0 | I39: =I15 -> 5 | J39: =J15 -> 7 | K39: =K15 -> 6 | L39: =L15 -> 5
B40: Severity Label Precision - LOW | C40: Description + File | D40: 0 | E40: 0.2 | G40: Overall (pr CWE ⊆ gt) | H40: 0.5 | I40: =I39+I16 -> 18 | J40: =J39+J16 -> 22 | K40: =K39+K16 -> 22 | L40: =L39+L16 -> 15
...

Sheet LLAMA Plots
C1: Percentage | G1: Baseline (Raw) | AA1: Generated By Python
B2: Metric | C2: Input Type | D2: Baseline | E2: Fine-tuned | G2: Metric | H2: Minimum Threshold | I2: Description + file | J2: Description + method | K2: Description + hunk | L2: Description
B3: Correct Is_vulnerable | C3: Description + File | D3: ='Vulnerability Detection - LLAMA'!B3/'Vulnerability Detection - LLAMA'!B38*100 -> 99.695122 | E3: ='Vulnerability Detection - LLAMA'!F3/'Vulnerability Detection - LLAMA'!B38*100 -> 100 | G3: Score Proximity | H3: 0 | I3: ='Vulnerability Detection - LLAMA'!B19 -> 16 | J3: ='Vulnerability Detection - LLAMA'!C19 -> 16 | K3: ='Vulnerability Detection - LLAMA'!D19 -> 6 | L3: ='Vulnerability Detection - LLAMA'!E19 -> 14
B4: Correct Is_vulnerable | C4: Description + Method | D4: ='Vulnerability Detection - LLAMA'!C3/'Vulnerability Detection - LLAMA'!B38*100 -> 100 | E4: ='Vulnerability Detection - LLAMA'!G3/'Vulnerability Detection - LLAMA'!B38*100 -> 100 | G4: Score Proximity | H4: 0.5 | I4: ='Vulnerability Detection - LLAMA'!B20 -> 31 | J4: ='Vulnerability Detection - LLAMA'!C20 -> 27 | K4: ='Vulnerability Detection - LLAMA'!D20 -> 37 | L4: ='Vulnerability Detection - LLAMA'!E20 -> 20
B5: Correct Is_vulnerable | C5: Description + Hunk | D5: ='Vulnerability Detection - LLAMA'!D3/'Vulnerability Detection - LLAMA'!B38*100 -> 100 | E5: ='Vulnerability Detection - LLAMA'!H3/'Vulnerability Detection - LLAMA'!B38*100 -> 100 | G5: Score Proximity | H5: 1 | I5: ='Vulnerability Detection - LLAMA'!B21 -> 56 | J5: ='Vulnerability Detection - LLAMA'!C21 -> 50 | K5: ='Vulnerability Detection - LLAMA'!D21 -> 48 | L5: ='Vulnerability Detection - LLAMA'!E21 -> 42
B6: Correct Is_vulnerable | C6: Description | D6: ='Vulnerability Detection - LLAMA'!E3/'Vulnerability Detection - LLAMA'!B38*100 -> 94.207317 | E6: ='Vulnerability Detection - LLAMA'!I3/'Vulnerability Detection - LLAMA'!B38*100 -> 100 | G6: Score Proximity | H6: 1.5 | I6: ='Vulnerability Detection - LLAMA'!B22 -> 42 | J6: ='Vulnerability Detection - LLAMA'!C22 -> 51 | K6: ='Vulnerability Detection - LLAMA'!D22 -> 51 | L6: ='Vulnerability Detection - LLAMA'!E22 -> 35
B7: Correct Is_sec_vulnerable | C7: Description + File | D7: ='Vulnerability Detection - LLAMA'!B6/'Vulnerability Detection - LLAMA'!B38*100 -> 99.695122 | E7: ='Vulnerability Detection - LLAMA'!F6/'Vulnerability Detection - LLAMA'!B38*100 -> 100 | G7: Baseline (Raw)
B8: Correct Is_sec_vulnerable | C8: Description + Method | D8: ='Vulnerability Detection - LLAMA'!C6/'Vulnerability Detection - LLAMA'!B38*100 -> 100 | E8: ='Vulnerability Detection - LLAMA'!G6/'Vulnerability Detection - LLAMA'!B38*100 -> 100 | G8: Metric | H8: Minimum Threshold | I8: Description + file | J8: Description + method | K8: Description + hunk | L8: Description
B9: Correct Is_sec_vulnerable | C9: Description + Hunk | D9: ='Vulnerability Detection - LLAMA'!D6/'Vulnerability Detection - LLAMA'!B38*100 -> 100 | E9: ='Vulnerability Detection - LLAMA'!H6/'Vulnerability Detection - LLAMA'!B38*100 -> 100 | G9: Overall (pr CWE = gt) | H9: 0 | I9: ='Vulnerability Detection - LLAMA'!B23 -> 0 | J9: ='Vulnerability Detection - LLAMA'!C23 -> 0 | K9: ='Vulnerability Detection - LLAMA'!D23 -> 0 | L9: ='Vulnerability Detection - LLAMA'!E23 -> 0
B10: Correct Is_sec_vulnerable | C10: Description | D10: ='Vulnerability Detection - LLAMA'!E6/'Vulnerability Detection - LLAMA'!B38*100 -> 94.512195 | E10: ='Vulnerability Detection - LLAMA'!I6/'Vulnerability Detection - LLAMA'!B38*100 -> 100 | G10: Overall (pr CWE = gt) | H10: 0.5 | I10: ='Vulnerability Detection - LLAMA'!B24 -> 0 | J10: ='Vulnerability Detection - LLAMA'!C24 -> 0 | K10: ='Vulnerability Detection - LLAMA'!D24 -> 0 | L10: ='Vulnerability Detection - LLAMA'!E24 -> 0
B11: Empty CWE | C11: Description + File | D11: ='Vulnerability Detection - LLAMA'!B9/'Vulnerability Detection - LLAMA'!B38*100 -> 0 | E11: ='Vulnerability Detection - LLAMA'!F9/'Vulnerability Detection - LLAMA'!B38*100 -> 0 | G11: Overall (pr CWE = gt) | H11: 1 | I11: ='Vulnerability Detection - LLAMA'!B25 -> 0 | J11: ='Vulnerability Detection - LLAMA'!C25 -> 0 | K11: ='Vulnerability Detection - LLAMA'!D25 -> 0 | L11: ='Vulnerability Detection - LLAMA'!E25 -> 0
B12: Empty CWE | C12: Description + Method | D12: ='Vulnerability Detection - LLAMA'!C9/'Vulnerability Detection - LLAMA'!B38*100 -> 0 | E12: ='Vulnerability Detection - LLAMA'!G9/'Vulnerability Detection - LLAMA'!B38*100 -> 0 | G12: Overall (pr CWE = gt) | H12: 1.5 | I12: ='Vulnerability Detection - LLAMA'!B26 -> 0 | J12: ='Vulnerability Detection - LLAMA'!C26 -> 0 | K12: ='Vulnerability Detection - LLAMA'!D26 -> 0 | L12: ='Vulnerability Detection - LLAMA'!E26 -> 0
B13: Empty CWE | C13: Description + Hunk | D13: ='Vulnerability Detection - LLAMA'!D9/'Vulnerability Detection - LLAMA'!B38*100 -> 0 | E13: ='Vulnerability Detection - LLAMA'!H9/'Vulnerability Detection - LLAMA'!B38*100 -> 0 | G13: Baseline (Raw)
B14: Empty CWE | C14: Description | D14: ='Vulnerability Detection - LLAMA'!E9/'Vulnerability Detection - LLAMA'!B38*100 -> 3.3536585 | E14: ='Vulnerability Detection - LLAMA'!I9/'Vulnerability Detection - LLAMA'!B38*100 -> 0 | G14: Metric | H14: Minimum Threshold | I14: Description + file | J14: Description + method | K14: Description + hunk | L14: Description
B15: Correct CWE | C15: Description + File | D15: ='Vulnerability Detection - LLAMA'!B10/'Vulnerability Detection - LLAMA'!B38*100 -> 0 | E15: ='Vulnerability Detection - LLAMA'!F10/'Vulnerability Detection - LLAMA'!B38*100 -> 28.963415 | G15: Overall (pr CWE ⊆ gt) | H15: 0 | I15: ='Vulnerability Detection - LLAMA'!B27 -> 0 | J15: ='Vulnerability Detection - LLAMA'!C27 -> 0 | K15: ='Vulnerability Detection - LLAMA'!D27 -> 0 | L15: ='Vulnerability Detection - LLAMA'!E27 -> 0
B16: Correct CWE | C16: Description + Method | D16: ='Vulnerability Detection - LLAMA'!C10/'Vulnerability Detection - LLAMA'!B38*100 -> 0 | E16: ='Vulnerability Detection - LLAMA'!G10/'Vulnerability Detection - LLAMA'!B38*100 -> 32.012195 | G16: Overall (pr CWE ⊆ gt) | H16: 0.5 | I16: ='Vulnerability Detection - LLAMA'!B28 -> 2 | J16: ='Vulnerability Detection - LLAMA'!C28 -> 2 | K16: ='Vulnerability Detection - LLAMA'!D28 -> 2 | L16: ='Vulnerability Detection - LLAMA'!E28 -> 2
B17: Correct CWE | C17: Description + Hunk | D17: ='Vulnerability Detection - LLAMA'!D10/'Vulnerability Detection - LLAMA'!B38*100 -> 0 | E17: ='Vulnerability Detection - LLAMA'!H10/'Vulnerability Detection - LLAMA'!B38*100 -> 31.707317 | G17: Overall (pr CWE ⊆ gt) | H17: 1 | I17: ='Vulnerability Detection - LLAMA'!B29 -> 0 | J17: ='Vulnerability Detection - LLAMA'!C29 -> 0 | K17: ='Vulnerability Detection - LLAMA'!D29 -> 0 | L17: ='Vulnerability Detection - LLAMA'!E29 -> 0
B18: Correct CWE | C18: Description | D18: ='Vulnerability Detection - LLAMA'!E10/'Vulnerability Detection - LLAMA'!B38*100 -> 0 | E18: ='Vulnerability Detection - LLAMA'!I10/'Vulnerability Detection - LLAMA'!B38*100 -> 34.45122 | G18: Overall (pr CWE ⊆ gt) | H18: 1.5 | I18: ='Vulnerability Detection - LLAMA'!B30 -> 0 | J18: ='Vulnerability Detection - LLAMA'!C30 -> 0 | K18: ='Vulnerability Detection - LLAMA'!D30 -> 0 | L18: ='Vulnerability Detection - LLAMA'!E30 -> 0
B19: gt CWE ⊆ pr CWE | C19: Description + File | D19: ='Vulnerability Detection - LLAMA'!B11/'Vulnerability Detection - LLAMA'!B38*100 -> 14.02439 | E19: ='Vulnerability Detection - LLAMA'!F11/'Vulnerability Detection - LLAMA'!B38*100 -> 28.963415 | G19: Baseline (Raw)
B20: gt CWE ⊆ pr CWE | C20: Description + Method | D20: ='Vulnerability Detection - LLAMA'!C11/'Vulnerability Detection - LLAMA'!B38*100 -> 15.853659 | E20: ='Vulnerability Detection - LLAMA'!G11/'Vulnerability Detection - LLAMA'!B38*100 -> 32.012195 | G20: Metric | H20: Minimum Threshold | I20: Description + file | J20: Description + method | K20: Description + hunk | L20: Description
B21: gt CWE ⊆ pr CWE | C21: Description + Hunk | D21: ='Vulnerability Detection - LLAMA'!D11/'Vulnerability Detection - LLAMA'!B38*100 -> 14.939024 | E21: ='Vulnerability Detection - LLAMA'!H11/'Vulnerability Detection - LLAMA'!B38*100 -> 31.707317 | G21: Overall (gt CWE ⊆ pr) | H21: 0 | I21: ='Vulnerability Detection - LLAMA'!B31 -> 4 | J21: ='Vulnerability Detection - LLAMA'!C31 -> 12 | K21: ='Vulnerability Detection - LLAMA'!D31 -> 4 | L21: ='Vulnerability Detection - LLAMA'!E31 -> 11
B22: gt CWE ⊆ pr CWE | C22: Description | D22: ='Vulnerability Detection - LLAMA'!E11/'Vulnerability Detection - LLAMA'!B38*100 -> 17.682927 | E22: ='Vulnerability Detection - LLAMA'!I11/'Vulnerability Detection - LLAMA'!B38*100 -> 34.45122 | G22: Overall (gt CWE ⊆ pr) | H22: 0.5 | I22: ='Vulnerability Detection - LLAMA'!B32 -> 9 | J22: ='Vulnerability Detection - LLAMA'!C32 -> 0 | K22: ='Vulnerability Detection - LLAMA'!D32 -> 9 | L22: ='Vulnerability Detection - LLAMA'!E32 -> 2
B23: pr CWE ⊆ gt CWE | C23: Description + File | D23: ='Vulnerability Detection - LLAMA'!B12/'Vulnerability Detection - LLAMA'!B38*100 -> 0.6097561 | E23: ='Vulnerability Detection - LLAMA'!F12/'Vulnerability Detection - LLAMA'!B38*100 -> 32.926829 | G23: Overall (gt CWE ⊆ pr) | H23: 1 | I23: ='Vulnerability Detection - LLAMA'!B33 -> 10 | J23: ='Vulnerability Detection - LLAMA'!C33 -> 3 | K23: ='Vulnerability Detection - LLAMA'!D33 -> 7 | L23: ='Vulnerability Detection - LLAMA'!E33 -> 6
B24: pr CWE ⊆ gt CWE | C24: Description + Method | D24: ='Vulnerability Detection - LLAMA'!C12/'Vulnerability Detection - LLAMA'!B38*100 -> 0.6097561 | E24: ='Vulnerability Detection - LLAMA'!G12/'Vulnerability Detection - LLAMA'!B38*100 -> 35.97561 | G24: Overall (gt CWE ⊆ pr) | H24: 1.5 | I24: ='Vulnerability Detection - LLAMA'!B34 -> 0 | J24: ='Vulnerability Detection - LLAMA'!C34 -> 16 | K24: ='Vulnerability Detection - LLAMA'!D34 -> 8 | L24: ='Vulnerability Detection - LLAMA'!E34 -> 12
B25: pr CWE ⊆ gt CWE | C25: Description + Hunk | D25: ='Vulnerability Detection - LLAMA'!D12/'Vulnerability Detection - LLAMA'!B38*100 -> 0.6097561 | E25: ='Vulnerability Detection - LLAMA'!H12/'Vulnerability Detection - LLAMA'!B38*100 -> 36.280488 | G25: Baseline (Cumulative)
B26: pr CWE ⊆ gt CWE | C26: Description | D26: ='Vulnerability Detection - LLAMA'!E12/'Vulnerability Detection - LLAMA'!B38*100 -> 0.6097561 | E26: ='Vulnerability Detection - LLAMA'!I12/'Vulnerability Detection - LLAMA'!B38*100 -> 38.414634 | G26: Metric | H26: Threshold to cover | I26: Description + file | J26: Description + method | K26: Description + hunk | L26: Description
B27: Overlapped CWE | C27: Description + File | D27: ='Vulnerability Detection - LLAMA'!B13/'Vulnerability Detection - LLAMA'!B38*100 -> 3.3536585 | E27: ='Vulnerability Detection - LLAMA'!F13/'Vulnerability Detection - LLAMA'!B38*100 -> 0 | G27: Score Proximity | H27: 0 | I27: =I3 -> 16 | J27: =J3 -> 16 | K27: =K3 -> 6 | L27: =L3 -> 14
B28: Overlapped CWE | C28: Description + Method | D28: ='Vulnerability Detection - LLAMA'!C13/'Vulnerability Detection - LLAMA'!B38*100 -> 2.4390244 | E28: ='Vulnerability Detection - LLAMA'!G13/'Vulnerability Detection - LLAMA'!B38*100 -> 0 | G28: Score Proximity | H28: 0.5 | I28: =I27+I4 -> 47 | J28: =J27+J4 -> 43 | K28: =K27+K4 -> 43 | L28: =L27+L4 -> 34
B29: Overlapped CWE | C29: Description + Hunk | D29: ='Vulnerability Detection - LLAMA'!D13/'Vulnerability Detection - LLAMA'!B38*100 -> 2.4390244 | E29: ='Vulnerability Detection - LLAMA'!H13/'Vulnerability Detection - LLAMA'!B38*100 -> 0 | G29: Score Proximity | H29: 1 | I29: =I28+I5 -> 103 | J29: =J28+J5 -> 93 | K29: =K28+K5 -> 91 | L29: =L28+L5 -> 76
B30: Overlapped CWE | C30: Description | D30: ='Vulnerability Detection - LLAMA'!E13/'Vulnerability Detection - LLAMA'!B38*100 -> 3.0487805 | E30: ='Vulnerability Detection - LLAMA'!I13/'Vulnerability Detection - LLAMA'!B38*100 -> 0 | G30: Score Proximity | H30: 1.5 | I30: =I29+I6 -> 145 | J30: =J29+J6 -> 144 | K30: =K29+K6 -> 142 | L30: =L29+L6 -> 111
B31: Non-overlapped CWE | C31: Description + File | D31: ='Vulnerability Detection - LLAMA'!B14/'Vulnerability Detection - LLAMA'!B38*100 -> 81.707317 | E31: ='Vulnerability Detection - LLAMA'!F14/'Vulnerability Detection - LLAMA'!B38*100 -> 67.073171 | G31: Baseline (Cumulative)
B32: Non-overlapped CWE | C32: Description + Method | D32: ='Vulnerability Detection - LLAMA'!C14/'Vulnerability Detection - LLAMA'!B38*100 -> 81.097561 | E32: ='Vulnerability Detection - LLAMA'!G14/'Vulnerability Detection - LLAMA'!B38*100 -> 64.02439 | G32: Metric | H32: Threshold to cover | I32: Description + file | J32: Description + method | K32: Description + hunk | L32: Description
B33: Non-overlapped CWE | C33: Description + Hunk | D33: ='Vulnerability Detection - LLAMA'!D14/'Vulnerability Detection - LLAMA'!B38*100 -> 82.012195 | E33: ='Vulnerability Detection - LLAMA'!H14/'Vulnerability Detection - LLAMA'!B38*100 -> 63.719512 | G33: Overall (pr CWE = gt) | H33: 0 | I33: =I9 -> 0 | J33: =J9 -> 0 | K33: =K9 -> 0 | L33: =L9 -> 0
B34: Non-overlapped CWE | C34: Description | D34: ='Vulnerability Detection - LLAMA'!E14/'Vulnerability Detection - LLAMA'!B38*100 -> 72.865854 | E34: ='Vulnerability Detection - LLAMA'!I14/'Vulnerability Detection - LLAMA'!B38*100 -> 61.585366 | G34: Overall (pr CWE = gt) | H34: 0.5 | I34: =I33+I10 -> 0 | J34: =J33+J10 -> 0 | K34: =K33+K10 -> 0 | L34: =L33+L10 -> 0
B35: Correct severity | C35: Description + File | D35: ='Vulnerability Detection - LLAMA'!B16/'Vulnerability Detection - LLAMA'!B38*100 -> 32.317073 | E35: ='Vulnerability Detection - LLAMA'!F16/'Vulnerability Detection - LLAMA'!B38*100 -> 46.646341 | G35: Overall (pr CWE = gt) | H35: 1 | I35: =I34+I11 -> 0 | J35: =J34+J11 -> 0 | K35: =K34+K11 -> 0 | L35: =L34+L11 -> 0
B36: Correct severity | C36: Description + Method | D36: ='Vulnerability Detection - LLAMA'!C16/'Vulnerability Detection - LLAMA'!B38*100 -> 42.378049 | E36: ='Vulnerability Detection - LLAMA'!G16/'Vulnerability Detection - LLAMA'!B38*100 -> 42.682927 | G36: Overall (pr CWE = gt) | H36: 1.5 | I36: =I35+I12 -> 0 | J36: =J35+J12 -> 0 | K36: =K35+K12 -> 0 | L36: =L35+L12 -> 0
B37: Correct severity | C37: Description + Hunk | D37: ='Vulnerability Detection - LLAMA'!D16/'Vulnerability Detection - LLAMA'!B38*100 -> 47.865854 | E37: ='Vulnerability Detection - LLAMA'!H16/'Vulnerability Detection - LLAMA'!B38*100 -> 52.743902 | G37: Baseline (Cumulative)
B38: Correct severity | C38: Description | D38: ='Vulnerability Detection - LLAMA'!E16/'Vulnerability Detection - LLAMA'!B38*100 -> 35.97561 | E38: ='Vulnerability Detection - LLAMA'!I16/'Vulnerability Detection - LLAMA'!B38*100 -> 48.170732 | G38: Metric | H38: Threshold to cover | I38: Description + file | J38: Description + method | K38: Description + hunk | L38: Description
G39: Overall (pr CWE ⊆ gt) | H39: 0 | I39: =I15 -> 0 | J39: =J15 -> 0 | K39: =K15 -> 0 | L39: =L15 -> 0
B40: Severity Label Precision - LOW | C40: Description + File | D40: 0.2 | E40: 0 | G40: Overall (pr CWE ⊆ gt) | H40: 0.5 | I40: =I39+I16 -> 2 | J40: =J39+J16 -> 2 | K40: =K39+K16 -> 2 | L40: =L39+L16 -> 2
...

Sheet Compare with baselines
A1: CWE (SINGLE - FILE) (PE)
B2: Paper Baseline (GPT) | E2: Paper Baseline (LLaMA)
A3: PE (NONE) | B3: 2.61 | D3: PE (NONE) | E3: 0.65
B4: Paper Baseline (GPT) | E4: Paper Baseline (LLaMA)
A5: PE (ROLE) | B5: 0 | D5: PE (ROLE) | E5: 7.52
B6: Paper Baseline (GPT) | E6: Paper Baseline (LLaMA)
A7: PE (COT) | B7: 10.78 | D7: PE (COT) | E7: 1.34
A9: CWE (SINGLE - METHOD) (PE)
B10: Paper Baseline (GPT) | E10: Paper Baseline (LLaMA)
A11: PE (NONE) | B11: 3.91 | D11: PE (NONE) | E11: 1.32
B12: Paper Baseline (GPT) | E12: Paper Baseline (LLaMA)
A13: PE (ROLE) | B13: 0 | D13: PE (ROLE) | E13: 3.82
B14: Paper Baseline (GPT) | E14: Paper Baseline (LLaMA)
A15: PE (COT) | B15: 12.28 | D15: PE (COT) | E15: 5.08
A17: CWE (MULTI - FILE) (PE)
B18: Paper Baseline (GPT) | E18: Paper Baseline (LLaMA)
A19: PE (NONE) | B19: 3.39 | D19: PE (NONE) | E19: 0.65
B20: Paper Baseline (GPT) | E20: Paper Baseline (LLaMA)
A21: PE (ROLE) | B21: 0 | D21: PE (ROLE) | E21: 7.76
B22: Paper Baseline (GPT) | E22: Paper Baseline (LLaMA)
A23: PE (COT) | B23: 8.33 | D23: PE (COT) | E23: 1.34
A25: CWE (MULTI - METHOD) (PE)
B26: Paper Baseline (GPT) | E26: Paper Baseline (LLaMA)
A27: PE (NONE) | B27: 0 | D27: PE (NONE) | E27: 0.66
B28: Paper Baseline (GPT) | E28: Paper Baseline (LLaMA)
A29: PE (ROLE) | B29: 0 | D29: PE (ROLE) | E29: 6.13
B30: Paper Baseline (GPT) | E30: Paper Baseline (LLaMA)
A31: PE (COT) | B31: 10.12 | D31: PE (COT) | E31: 6.06
A34: Severity Label - Baseline 1 (severity generator with ICL) (SLA)
B35: Paper Baseline (GPT) | E35: Paper Baseline (LLaMA)
A36: SLA | B36: 37.5 | E36: 40.85
